Workbook

Sheet Catalog
A1: ID | B1: UPC2 | C1: ISRC | D1: Tracks, Albums, Content | E1: Artist Name | F1: Release Date | G1: LABEL | H1: LABEL % | I1: Unique Artist Name | J1: Artist 1 | K1: Artist 1 % | L1: Artist 2 | M1: Artist 2 % | N1: Artist 3 | O1: Artist 3 % | P1: Artist 4 | Q1: Artist 4 % | R1: Artist 5 | S1: Artist 5 % | T1: Artist 6 | U1: Artist 6 % | V1: Artist 7 | W1: Artist 7 % | X1: Artist 8 | Y1: Artist 8 % | Z1: Artist 9 | AA1: Artist 9%
A2: 3617054108995FR-S18-22-65715 | B2: 3617054108995 | C2: FR-S18-22-65715 | D2: 44902 | E2: Los Dos Carnales | G2: AfinArte | H2: =100%-SUM(CatalogTable[[#This Row],[Artist 1 %]],CatalogTable[[#This Row],[Artist 2 %]],CatalogTable[[#This Row],[Artist 3 %]],CatalogTable[[#This Row],[Artist 4 %]],CatalogTable[[#This Row],[Artist 5 %]],CatalogTable[[#This Row],[Artist 6 %]],CatalogTable[[#This Row],[Artist 7 %]],CatalogTable[[#This Row],[Artist 8 %]],CatalogTable[[#This Row],[Artist 9%]]) -> 0.9 | I2: =IF(ISBLANK(E2),"",INDEX(UniqueArtist!B:B, MATCH(E2,UniqueArtist!A:A, 0))) -> Los Dos Carnales | J2: =IFERROR(TRIM(LEFT(I2, IFERROR(FIND(",", I2)-1, LEN(I2)))), "") -> Los Dos Carnales | K2: 0.1 | L2: =IFERROR(TRIM(MID(I2, FIND(",", I2) + 1, IFERROR(FIND(",", I2, FIND(",", I2) + 1) - FIND(",", I2) - 1, LEN(I2)))), "") | N2: =IFERROR(TRIM(MID(I2, FIND(",", I2, FIND(",", I2) + 1) + 1, IFERROR(FIND(",", I2, FIND(",", I2, FIND(",", I2) + 1) + 1) - FIND(",", I2, FIND(",", I2) + 1) - 1, LEN(I2)))), "") | P2: =IFERROR(TRIM(MID(I2, FIND(",", I2, FIND(",", I2, FIND(",", I2) + 1) + 1) + 1, IFERROR(FIND(",", I2, FIND(",", I2, FIND(",", I2, FIND(",", I2) + 1) + 1) + 1) - FIND(",", I2, FIND(",", I2, FIND(",", I2) + 1) + 1) - 1, LEN(I2)))), "") | R2: =IFERROR(TRIM(MID(I2, FIND(",", I2, FIND(",", I2, FIND(",", I2, FIND(",", I2) + 1) + 1) + 1) + 1, IFERROR(FIND(",", I2, FIND(",", I2, FIND(",", I2, FIND(",", I2, FIND(",", I2) + 1) + 1) + 1) + 1) - FIND(",", I2, FIND(",", I2, FIND(",", I2, FIND(",", I2) + 1) + 1) + 1) - 1, LEN(I2)))), "") | T2: =IFERROR(TRIM(MID(I2, FIND(",", I2, FIND(",", I2, FIND(",", I2, FIND(",", I2, FIND(",", I2, FIND(",", I2) + 1) + 1) + 1) + 1) + 1) + 1, IFERROR(FIND(",", I2, FIND(",", I2, FIND(",", I2, FIND(",", I2, FIND(",", I2, FIND(",", I2) + 1) + 1) + 1) + 1) + 1) - FIND(",", I2, FIND(",", I2, FIND(",", I2, FIND(",", I2, FIND(",", I2) + 1) + 1) + 1) + 1) - 1, LEN(I2)))), "") | V2: =IFERROR(TRIM(MID(I2, FIND(",", I2, FIND(",", I2, FIND(",", I2, FIND(",", I2, FIND(",", I2, FIND(",", I2, FIND(",", I2) + 1) + 1) + 1) + 1) + 1) + 1) + 1, IFERROR(FIND(",", I2, FIND(",", I2, FIND(",", I2, FIND(",", I2, FIND(",", I2, FIND(",", I2, FIND(",", I2) + 1) + 1) + 1) + 1) + 1) + 1) - FIND(",", I2, FIND(",", I2, FIND(",", I2, FIND(",", I2, FIND(",", I2, FIND(",", I2) + 1) + 1) + 1) + 1) + 1) - 1, LEN(I2)))), "") | X2: =IFERROR(TRIM(MID(I2, FIND(",", I2, FIND(",", I2, FIND(",", I2, FIND(",", I2, FIND(",", I2, FIND(",", I2, FIND(",", I2, FIND(",", I2) + 1) + 1) + 1) + 1) + 1) + 1) + 1) + 1, IFERROR(FIND(",", I2, FIND(",", I2, FIND(",", I2, FIND(",", I2, FIND(",", I2, FIND(",", I2, FIND(",", I2, FIND(",", I2) + 1) + 1) + 1) + 1) + 1) + 1) + 1) - FIND(",", I2, FIND(",", I2, FIND(",", I2, FIND(",", I2, FIND(",", I2, FIND(",", I2, FIND(",", I2) + 1) + 1) + 1) + 1) + 1) + 1) - 1, LEN(I2)))), "") | Z2: =IFERROR(TRIM(MID(I2, FIND(",", I2, FIND(",", I2, FIND(",", I2, FIND(",", I2, FIND(",", I2, FIND(",", I2, FIND(",", I2, FIND(",", I2, FIND(",", I2) + 1) + 1) + 1) + 1) + 1) + 1) + 1) + 1) + 1, IFERROR(FIND(",", I2, FIND(",", I2, FIND(",", I2, FIND(",", I2, FIND(",", I2, FIND(",", I2, FIND(",", I2, FIND(",", I2, FIND(",", I2) + 1) + 1) + 1) + 1) + 1) + 1) + 1) + 1) - FIND(",", I2, FIND(",", I2, FIND(",", I2, FIND(",", I2, FIND(",", I2, FIND(",", I2, FIND(",", I2, FIND(",", I2) + 1) + 1) + 1) + 1) + 1) + 1) + 1) - 1, LEN(I2)))), "")
A3: 3617050147738FR-X99-22-26351 | B3: 3617050147738 | C3: FR-X99-22-26351 | D3: ¡Azzzzzucar! #ElFantasma | E3: El Fantasma | G3: AfinArte | H3: =100%-SUM(CatalogTable[[#This Row],[Artist 1 %]],CatalogTable[[#This Row],[Artist 2 %]],CatalogTable[[#This Row],[Artist 3 %]],CatalogTable[[#This Row],[Artist 4 %]],CatalogTable[[#This Row],[Artist 5 %]],CatalogTable[[#This Row],[Artist 6 %]],CatalogTable[[#This Row],[Artist 7 %]],CatalogTable[[#This Row],[Artist 8 %]],CatalogTable[[#This Row],[Artist 9%]]) -> 0.65 | I3: =IF(ISBLANK(E3),"",INDEX(UniqueArtist!B:B, MATCH(E3,UniqueArtist!A:A, 0))) -> El Fantasma | J3: =IFERROR(TRIM(LEFT(I3, IFERROR(FIND(",", I3)-1, LEN(I3)))), "") -> El Fantasma | K3: 0.35 | L3: =IFERROR(TRIM(MID(I3, FIND(",", I3) + 1, IFERROR(FIND(",", I3, FIND(",", I3) + 1) - FIND(",", I3) - 1, LEN(I3)))), "") | N3: =IFERROR(TRIM(MID(I3, FIND(",", I3, FIND(",", I3) + 1) + 1, IFERROR(FIND(",", I3, FIND(",", I3, FIND(",", I3) + 1) + 1) - FIND(",", I3, FIND(",", I3) + 1) - 1, LEN(I3)))), "") | P3: =IFERROR(TRIM(MID(I3, FIND(",", I3, FIND(",", I3, FIND(",", I3) + 1) + 1) + 1, IFERROR(FIND(",", I3, FIND(",", I3, FIND(",", I3, FIND(",", I3) + 1) + 1) + 1) - FIND(",", I3, FIND(",", I3, FIND(",", I3) + 1) + 1) - 1, LEN(I3)))), "") | R3: =IFERROR(TRIM(MID(I3, FIND(",", I3, FIND(",", I3, FIND(",", I3, FIND(",", I3) + 1) + 1) + 1) + 1, IFERROR(FIND(",", I3, FIND(",", I3, FIND(",", I3, FIND(",", I3, FIND(",", I3) + 1) + 1) + 1) + 1) - FIND(",", I3, FIND(",", I3, FIND(",", I3, FIND(",", I3) + 1) + 1) + 1) - 1, LEN(I3)))), "") | T3: =IFERROR(TRIM(MID(I3, FIND(",", I3, FIND(",", I3, FIND(",", I3, FIND(",", I3, FIND(",", I3, FIND(",", I3) + 1) + 1) + 1) + 1) + 1) + 1, IFERROR(FIND(",", I3, FIND(",", I3, FIND(",", I3, FIND(",", I3, FIND(",", I3, FIND(",", I3) + 1) + 1) + 1) + 1) + 1) - FIND(",", I3, FIND(",", I3, FIND(",", I3, FIND(",", I3, FIND(",", I3) + 1) + 1) + 1) + 1) - 1, LEN(I3)))), "") | V3: =IFERROR(TRIM(MID(I3, FIND(",", I3, FIND(",", I3, FIND(",", I3, FIND(",", I3, FIND(",", I3, FIND(",", I3, FIND(",", I3) + 1) + 1) + 1) + 1) + 1) + 1) + 1, IFERROR(FIND(",", I3, FIND(",", I3, FIND(",", I3, FIND(",", I3, FIND(",", I3, FIND(",", I3, FIND(",", I3) + 1) + 1) + 1) + 1) + 1) + 1) - FIND(",", I3, FIND(",", I3, FIND(",", I3, FIND(",", I3, FIND(",", I3, FIND(",", I3) + 1) + 1) + 1) + 1) + 1) - 1, LEN(I3)))), "") | X3: =IFERROR(TRIM(MID(I3, FIND(",", I3, FIND(",", I3, FIND(",", I3, FIND(",", I3, FIND(",", I3, FIND(",", I3, FIND(",", I3, FIND(",", I3) + 1) + 1) + 1) + 1) + 1) + 1) + 1) + 1, IFERROR(FIND(",", I3, FIND(",", I3, FIND(",", I3, FIND(",", I3, FIND(",", I3, FIND(",", I3, FIND(",", I3, FIND(",", I3) + 1) + 1) + 1) + 1) + 1) + 1) + 1) - FIND(",", I3, FIND(",", I3, FIND(",", I3, FIND(",", I3, FIND(",", I3, FIND(",", I3, FIND(",", I3) + 1) + 1) + 1) + 1) + 1) + 1) - 1, LEN(I3)))), "") | Z3: =IFERROR(TRIM(MID(I3, FIND(",", I3, FIND(",", I3, FIND(",", I3, FIND(",", I3, FIND(",", I3, FIND(",", I3, FIND(",", I3, FIND(",", I3, FIND(",", I3) + 1) + 1) + 1) + 1) + 1) + 1) + 1) + 1) + 1, IFERROR(FIND(",", I3, FIND(",", I3, FIND(",", I3, FIND(",", I3, FIND(",", I3, FIND(",", I3, FIND(",", I3, FIND(",", I3, FIND(",", I3) + 1) + 1) + 1) + 1) + 1) + 1) + 1) + 1) - FIND(",", I3, FIND(",", I3, FIND(",", I3, FIND(",", I3, FIND(",", I3, FIND(",", I3, FIND(",", I3, FIND(",", I3) + 1) + 1) + 1) + 1) + 1) + 1) + 1) - 1, LEN(I3)))), "")
A4: 3617223765318FR-X99-23-93640 | B4: 3617223765318 | C4: FR-X99-23-93640 | D4: ¡Esperen al final! 😎😂 #ElParrandero #JrSalazar #Shorts #ShorteVideo #Fun #newrelease | E4: AfinArte Music | G4: AfinArte | H4: =100%-SUM(CatalogTable[[#This Row],[Artist 1 %]],CatalogTable[[#This Row],[Artist 2 %]],CatalogTable[[#This Row],[Artist 3 %]],CatalogTable[[#This Row],[Artist 4 %]],CatalogTable[[#This Row],[Artist 5 %]],CatalogTable[[#This Row],[Artist 6 %]],CatalogTable[[#This Row],[Artist 7 %]],CatalogTable[[#This Row],[Artist 8 %]],CatalogTable[[#This Row],[Artist 9%]]) -> 0 | I4: =IF(ISBLANK(E4),"",INDEX(UniqueArtist!B:B, MATCH(E4,UniqueArtist!A:A, 0))) -> AfinArte Music | J4: =IFERROR(TRIM(LEFT(I4, IFERROR(FIND(",", I4)-1, LEN(I4)))), "") -> AfinArte Music | K4: 1 | L4: =IFERROR(TRIM(MID(I4, FIND(",", I4) + 1, IFERROR(FIND(",", I4, FIND(",", I4) + 1) - FIND(",", I4) - 1, LEN(I4)))), "") | N4: =IFERROR(TRIM(MID(I4, FIND(",", I4, FIND(",", I4) + 1) + 1, IFERROR(FIND(",", I4, FIND(",", I4, FIND(",", I4) + 1) + 1) - FIND(",", I4, FIND(",", I4) + 1) - 1, LEN(I4)))), "") | P4: =IFERROR(TRIM(MID(I4, FIND(",", I4, FIND(",", I4, FIND(",", I4) + 1) + 1) + 1, IFERROR(FIND(",", I4, FIND(",", I4, FIND(",", I4, FIND(",", I4) + 1) + 1) + 1) - FIND(",", I4, FIND(",", I4, FIND(",", I4) + 1) + 1) - 1, LEN(I4)))), "") | R4: =IFERROR(TRIM(MID(I4, FIND(",", I4, FIND(",", I4, FIND(",", I4, FIND(",", I4) + 1) + 1) + 1) + 1, IFERROR(FIND(",", I4, FIND(",", I4, FIND(",", I4, FIND(",", I4, FIND(",", I4) + 1) + 1) + 1) + 1) - FIND(",", I4, FIND(",", I4, FIND(",", I4, FIND(",", I4) + 1) + 1) + 1) - 1, LEN(I4)))), "") | T4: =IFERROR(TRIM(MID(I4, FIND(",", I4, FIND(",", I4, FIND(",", I4, FIND(",", I4, FIND(",", I4, FIND(",", I4) + 1) + 1) + 1) + 1) + 1) + 1, IFERROR(FIND(",", I4, FIND(",", I4, FIND(",", I4, FIND(",", I4, FIND(",", I4, FIND(",", I4) + 1) + 1) + 1) + 1) + 1) - FIND(",", I4, FIND(",", I4, FIND(",", I4, FIND(",", I4, FIND(",", I4) + 1) + 1) + 1) + 1) - 1, LEN(I4)))), "") | V4: =IFERROR(TRIM(MID(I4, FIND(",", I4, FIND(",", I4, FIND(",", I4, FIND(",", I4, FIND(",", I4, FIND(",", I4, FIND(",", I4) + 1) + 1) + 1) + 1) + 1) + 1) + 1, IFERROR(FIND(",", I4, FIND(",", I4, FIND(",", I4, FIND(",", I4, FIND(",", I4, FIND(",", I4, FIND(",", I4) + 1) + 1) + 1) + 1) + 1) + 1) - FIND(",", I4, FIND(",", I4, FIND(",", I4, FIND(",", I4, FIND(",", I4, FIND(",", I4) + 1) + 1) + 1) + 1) + 1) - 1, LEN(I4)))), "") | X4: =IFERROR(TRIM(MID(I4, FIND(",", I4, FIND(",", I4, FIND(",", I4, FIND(",", I4, FIND(",", I4, FIND(",", I4, FIND(",", I4, FIND(",", I4) + 1) + 1) + 1) + 1) + 1) + 1) + 1) + 1, IFERROR(FIND(",", I4, FIND(",", I4, FIND(",", I4, FIND(",", I4, FIND(",", I4, FIND(",", I4, FIND(",", I4, FIND(",", I4) + 1) + 1) + 1) + 1) + 1) + 1) + 1) - FIND(",", I4, FIND(",", I4, FIND(",", I4, FIND(",", I4, FIND(",", I4, FIND(",", I4, FIND(",", I4) + 1) + 1) + 1) + 1) + 1) + 1) - 1, LEN(I4)))), "") | Z4: =IFERROR(TRIM(MID(I4, FIND(",", I4, FIND(",", I4, FIND(",", I4, FIND(",", I4, FIND(",", I4, FIND(",", I4, FIND(",", I4, FIND(",", I4, FIND(",", I4) + 1) + 1) + 1) + 1) + 1) + 1) + 1) + 1) + 1, IFERROR(FIND(",", I4, FIND(",", I4, FIND(",", I4, FIND(",", I4, FIND(",", I4, FIND(",", I4, FIND(",", I4, FIND(",", I4, FIND(",", I4) + 1) + 1) + 1) + 1) + 1) + 1) + 1) + 1) - FIND(",", I4, FIND(",", I4, FIND(",", I4, FIND(",", I4, FIND(",", I4, FIND(",", I4, FIND(",", I4, FIND(",", I4) + 1) + 1) + 1) + 1) + 1) + 1) + 1) - 1, LEN(I4)))), "")
A5: 3617055399231FR-W24-23-13929 | B5: 3617055399231 | C5: FR-W24-23-13929 | D5: ¡Estamos de vuelta!~~~~~~ #FantasmaClassics #2daTemporada #AfinArteMusic #ElFantasma | E5: El Fantasma | G5: AfinArte | H5: =100%-SUM(CatalogTable[[#This Row],[Artist 1 %]],CatalogTable[[#This Row],[Artist 2 %]],CatalogTable[[#This Row],[Artist 3 %]],CatalogTable[[#This Row],[Artist 4 %]],CatalogTable[[#This Row],[Artist 5 %]],CatalogTable[[#This Row],[Artist 6 %]],CatalogTable[[#This Row],[Artist 7 %]],CatalogTable[[#This Row],[Artist 8 %]],CatalogTable[[#This Row],[Artist 9%]]) -> 0.65 | I5: =IF(ISBLANK(E5),"",INDEX(UniqueArtist!B:B, MATCH(E5,UniqueArtist!A:A, 0))) -> El Fantasma | J5: =IFERROR(TRIM(LEFT(I5, IFERROR(FIND(",", I5)-1, LEN(I5)))), "") -> El Fantasma | K5: 0.35 | L5: =IFERROR(TRIM(MID(I5, FIND(",", I5) + 1, IFERROR(FIND(",", I5, FIND(",", I5) + 1) - FIND(",", I5) - 1, LEN(I5)))), "") | N5: =IFERROR(TRIM(MID(I5, FIND(",", I5, FIND(",", I5) + 1) + 1, IFERROR(FIND(",", I5, FIND(",", I5, FIND(",", I5) + 1) + 1) - FIND(",", I5, FIND(",", I5) + 1) - 1, LEN(I5)))), "") | P5: =IFERROR(TRIM(MID(I5, FIND(",", I5, FIND(",", I5, FIND(",", I5) + 1) + 1) + 1, IFERROR(FIND(",", I5, FIND(",", I5, FIND(",", I5, FIND(",", I5) + 1) + 1) + 1) - FIND(",", I5, FIND(",", I5, FIND(",", I5) + 1) + 1) - 1, LEN(I5)))), "") | R5: =IFERROR(TRIM(MID(I5, FIND(",", I5, FIND(",", I5, FIND(",", I5, FIND(",", I5) + 1) + 1) + 1) + 1, IFERROR(FIND(",", I5, FIND(",", I5, FIND(",", I5, FIND(",", I5, FIND(",", I5) + 1) + 1) + 1) + 1) - FIND(",", I5, FIND(",", I5, FIND(",", I5, FIND(",", I5) + 1) + 1) + 1) - 1, LEN(I5)))), "") | T5: =IFERROR(TRIM(MID(I5, FIND(",", I5, FIND(",", I5, FIND(",", I5, FIND(",", I5, FIND(",", I5, FIND(",", I5) + 1) + 1) + 1) + 1) + 1) + 1, IFERROR(FIND(",", I5, FIND(",", I5, FIND(",", I5, FIND(",", I5, FIND(",", I5, FIND(",", I5) + 1) + 1) + 1) + 1) + 1) - FIND(",", I5, FIND(",", I5, FIND(",", I5, FIND(",", I5, FIND(",", I5) + 1) + 1) + 1) + 1) - 1, LEN(I5)))), "") | V5: =IFERROR(TRIM(MID(I5, FIND(",", I5, FIND(",", I5, FIND(",", I5, FIND(",", I5, FIND(",", I5, FIND(",", I5, FIND(",", I5) + 1) + 1) + 1) + 1) + 1) + 1) + 1, IFERROR(FIND(",", I5, FIND(",", I5, FIND(",", I5, FIND(",", I5, FIND(",", I5, FIND(",", I5, FIND(",", I5) + 1) + 1) + 1) + 1) + 1) + 1) - FIND(",", I5, FIND(",", I5, FIND(",", I5, FIND(",", I5, FIND(",", I5, FIND(",", I5) + 1) + 1) + 1) + 1) + 1) - 1, LEN(I5)))), "") | X5: =IFERROR(TRIM(MID(I5, FIND(",", I5, FIND(",", I5, FIND(",", I5, FIND(",", I5, FIND(",", I5, FIND(",", I5, FIND(",", I5, FIND(",", I5) + 1) + 1) + 1) + 1) + 1) + 1) + 1) + 1, IFERROR(FIND(",", I5, FIND(",", I5, FIND(",", I5, FIND(",", I5, FIND(",", I5, FIND(",", I5, FIND(",", I5, FIND(",", I5) + 1) + 1) + 1) + 1) + 1) + 1) + 1) - FIND(",", I5, FIND(",", I5, FIND(",", I5, FIND(",", I5, FIND(",", I5, FIND(",", I5, FIND(",", I5) + 1) + 1) + 1) + 1) + 1) + 1) - 1, LEN(I5)))), "") | Z5: =IFERROR(TRIM(MID(I5, FIND(",", I5, FIND(",", I5, FIND(",", I5, FIND(",", I5, FIND(",", I5, FIND(",", I5, FIND(",", I5, FIND(",", I5, FIND(",", I5) + 1) + 1) + 1) + 1) + 1) + 1) + 1) + 1) + 1, IFERROR(FIND(",", I5, FIND(",", I5, FIND(",", I5, FIND(",", I5, FIND(",", I5, FIND(",", I5, FIND(",", I5, FIND(",", I5, FIND(",", I5) + 1) + 1) + 1) + 1) + 1) + 1) + 1) + 1) - FIND(",", I5, FIND(",", I5, FIND(",", I5, FIND(",", I5, FIND(",", I5, FIND(",", I5, FIND(",", I5, FIND(",", I5) + 1) + 1) + 1) + 1) + 1) + 1) + 1) - 1, LEN(I5)))), "")
A6: 3616842123998DG-A0D-21-15652 | B6: 3616842123998 | C6: DG-A0D-21-15652 | D6: ¡Este si es un buen taco señores! #elfantasma #afinartemusic #mexicanfood | E6: El Fantasma | G6: AfinArte | H6: =100%-SUM(CatalogTable[[#This Row],[Artist 1 %]],CatalogTable[[#This Row],[Artist 2 %]],CatalogTable[[#This Row],[Artist 3 %]],CatalogTable[[#This Row],[Artist 4 %]],CatalogTable[[#This Row],[Artist 5 %]],CatalogTable[[#This Row],[Artist 6 %]],CatalogTable[[#This Row],[Artist 7 %]],CatalogTable[[#This Row],[Artist 8 %]],CatalogTable[[#This Row],[Artist 9%]]) -> 0.65 | I6: =IF(ISBLANK(E6),"",INDEX(UniqueArtist!B:B, MATCH(E6,UniqueArtist!A:A, 0))) -> El Fantasma | J6: =IFERROR(TRIM(LEFT(I6, IFERROR(FIND(",", I6)-1, LEN(I6)))), "") -> El Fantasma | K6: 0.35 | L6: =IFERROR(TRIM(MID(I6, FIND(",", I6) + 1, IFERROR(FIND(",", I6, FIND(",", I6) + 1) - FIND(",", I6) - 1, LEN(I6)))), "") | N6: =IFERROR(TRIM(MID(I6, FIND(",", I6, FIND(",", I6) + 1) + 1, IFERROR(FIND(",", I6, FIND(",", I6, FIND(",", I6) + 1) + 1) - FIND(",", I6, FIND(",", I6) + 1) - 1, LEN(I6)))), "") | P6: =IFERROR(TRIM(MID(I6, FIND(",", I6, FIND(",", I6, FIND(",", I6) + 1) + 1) + 1, IFERROR(FIND(",", I6, FIND(",", I6, FIND(",", I6, FIND(",", I6) + 1) + 1) + 1) - FIND(",", I6, FIND(",", I6, FIND(",", I6) + 1) + 1) - 1, LEN(I6)))), "") | R6: =IFERROR(TRIM(MID(I6, FIND(",", I6, FIND(",", I6, FIND(",", I6, FIND(",", I6) + 1) + 1) + 1) + 1, IFERROR(FIND(",", I6, FIND(",", I6, FIND(",", I6, FIND(",", I6, FIND(",", I6) + 1) + 1) + 1) + 1) - FIND(",", I6, FIND(",", I6, FIND(",", I6, FIND(",", I6) + 1) + 1) + 1) - 1, LEN(I6)))), "") | T6: =IFERROR(TRIM(MID(I6, FIND(",", I6, FIND(",", I6, FIND(",", I6, FIND(",", I6, FIND(",", I6, FIND(",", I6) + 1) + 1) + 1) + 1) + 1) + 1, IFERROR(FIND(",", I6, FIND(",", I6, FIND(",", I6, FIND(",", I6, FIND(",", I6, FIND(",", I6) + 1) + 1) + 1) + 1) + 1) - FIND(",", I6, FIND(",", I6, FIND(",", I6, FIND(",", I6, FIND(",", I6) + 1) + 1) + 1) + 1) - 1, LEN(I6)))), "") | V6: =IFERROR(TRIM(MID(I6, FIND(",", I6, FIND(",", I6, FIND(",", I6, FIND(",", I6, FIND(",", I6, FIND(",", I6, FIND(",", I6) + 1) + 1) + 1) + 1) + 1) + 1) + 1, IFERROR(FIND(",", I6, FIND(",", I6, FIND(",", I6, FIND(",", I6, FIND(",", I6, FIND(",", I6, FIND(",", I6) + 1) + 1) + 1) + 1) + 1) + 1) - FIND(",", I6, FIND(",", I6, FIND(",", I6, FIND(",", I6, FIND(",", I6, FIND(",", I6) + 1) + 1) + 1) + 1) + 1) - 1, LEN(I6)))), "") | X6: =IFERROR(TRIM(MID(I6, FIND(",", I6, FIND(",", I6, FIND(",", I6, FIND(",", I6, FIND(",", I6, FIND(",", I6, FIND(",", I6, FIND(",", I6) + 1) + 1) + 1) + 1) + 1) + 1) + 1) + 1, IFERROR(FIND(",", I6, FIND(",", I6, FIND(",", I6, FIND(",", I6, FIND(",", I6, FIND(",", I6, FIND(",", I6, FIND(",", I6) + 1) + 1) + 1) + 1) + 1) + 1) + 1) - FIND(",", I6, FIND(",", I6, FIND(",", I6, FIND(",", I6, FIND(",", I6, FIND(",", I6, FIND(",", I6) + 1) + 1) + 1) + 1) + 1) + 1) - 1, LEN(I6)))), "") | Z6: =IFERROR(TRIM(MID(I6, FIND(",", I6, FIND(",", I6, FIND(",", I6, FIND(",", I6, FIND(",", I6, FIND(",", I6, FIND(",", I6, FIND(",", I6, FIND(",", I6) + 1) + 1) + 1) + 1) + 1) + 1) + 1) + 1) + 1, IFERROR(FIND(",", I6, FIND(",", I6, FIND(",", I6, FIND(",", I6, FIND(",", I6, FIND(",", I6, FIND(",", I6, FIND(",", I6, FIND(",", I6) + 1) + 1) + 1) + 1) + 1) + 1) + 1) + 1) - FIND(",", I6, FIND(",", I6, FIND(",", I6, FIND(",", I6, FIND(",", I6, FIND(",", I6, FIND(",", I6, FIND(",", I6) + 1) + 1) + 1) + 1) + 1) + 1) + 1) - 1, LEN(I6)))), "")
A7: 3616842202228DG-A0D-21-20565 | B7: 3616842202228 | C7: DG-A0D-21-20565 | D7: ¡Gracias por todo! #republicadominicana #ElFantasma #afinartemusic | E7: El Fantasma | G7: AfinArte | H7: =100%-SUM(CatalogTable[[#This Row],[Artist 1 %]],CatalogTable[[#This Row],[Artist 2 %]],CatalogTable[[#This Row],[Artist 3 %]],CatalogTable[[#This Row],[Artist 4 %]],CatalogTable[[#This Row],[Artist 5 %]],CatalogTable[[#This Row],[Artist 6 %]],CatalogTable[[#This Row],[Artist 7 %]],CatalogTable[[#This Row],[Artist 8 %]],CatalogTable[[#This Row],[Artist 9%]]) -> 0.65 | I7: =IF(ISBLANK(E7),"",INDEX(UniqueArtist!B:B, MATCH(E7,UniqueArtist!A:A, 0))) -> El Fantasma | J7: =IFERROR(TRIM(LEFT(I7, IFERROR(FIND(",", I7)-1, LEN(I7)))), "") -> El Fantasma | K7: 0.35 | L7: =IFERROR(TRIM(MID(I7, FIND(",", I7) + 1, IFERROR(FIND(",", I7, FIND(",", I7) + 1) - FIND(",", I7) - 1, LEN(I7)))), "") | N7: =IFERROR(TRIM(MID(I7, FIND(",", I7, FIND(",", I7) + 1) + 1, IFERROR(FIND(",", I7, FIND(",", I7, FIND(",", I7) + 1) + 1) - FIND(",", I7, FIND(",", I7) + 1) - 1, LEN(I7)))), "") | P7: =IFERROR(TRIM(MID(I7, FIND(",", I7, FIND(",", I7, FIND(",", I7) + 1) + 1) + 1, IFERROR(FIND(",", I7, FIND(",", I7, FIND(",", I7, FIND(",", I7) + 1) + 1) + 1) - FIND(",", I7, FIND(",", I7, FIND(",", I7) + 1) + 1) - 1, LEN(I7)))), "") | R7: =IFERROR(TRIM(MID(I7, FIND(",", I7, FIND(",", I7, FIND(",", I7, FIND(",", I7) + 1) + 1) + 1) + 1, IFERROR(FIND(",", I7, FIND(",", I7, FIND(",", I7, FIND(",", I7, FIND(",", I7) + 1) + 1) + 1) + 1) - FIND(",", I7, FIND(",", I7, FIND(",", I7, FIND(",", I7) + 1) + 1) + 1) - 1, LEN(I7)))), "") | T7: =IFERROR(TRIM(MID(I7, FIND(",", I7, FIND(",", I7, FIND(",", I7, FIND(",", I7, FIND(",", I7, FIND(",", I7) + 1) + 1) + 1) + 1) + 1) + 1, IFERROR(FIND(",", I7, FIND(",", I7, FIND(",", I7, FIND(",", I7, FIND(",", I7, FIND(",", I7) + 1) + 1) + 1) + 1) + 1) - FIND(",", I7, FIND(",", I7, FIND(",", I7, FIND(",", I7, FIND(",", I7) + 1) + 1) + 1) + 1) - 1, LEN(I7)))), "") | V7: =IFERROR(TRIM(MID(I7, FIND(",", I7, FIND(",", I7, FIND(",", I7, FIND(",", I7, FIND(",", I7, FIND(",", I7, FIND(",", I7) + 1) + 1) + 1) + 1) + 1) + 1) + 1, IFERROR(FIND(",", I7, FIND(",", I7, FIND(",", I7, FIND(",", I7, FIND(",", I7, FIND(",", I7, FIND(",", I7) + 1) + 1) + 1) + 1) + 1) + 1) - FIND(",", I7, FIND(",", I7, FIND(",", I7, FIND(",", I7, FIND(",", I7, FIND(",", I7) + 1) + 1) + 1) + 1) + 1) - 1, LEN(I7)))), "") | X7: =IFERROR(TRIM(MID(I7, FIND(",", I7, FIND(",", I7, FIND(",", I7, FIND(",", I7, FIND(",", I7, FIND(",", I7, FIND(",", I7, FIND(",", I7) + 1) + 1) + 1) + 1) + 1) + 1) + 1) + 1, IFERROR(FIND(",", I7, FIND(",", I7, FIND(",", I7, FIND(",", I7, FIND(",", I7, FIND(",", I7, FIND(",", I7, FIND(",", I7) + 1) + 1) + 1) + 1) + 1) + 1) + 1) - FIND(",", I7, FIND(",", I7, FIND(",", I7, FIND(",", I7, FIND(",", I7, FIND(",", I7, FIND(",", I7) + 1) + 1) + 1) + 1) + 1) + 1) - 1, LEN(I7)))), "") | Z7: =IFERROR(TRIM(MID(I7, FIND(",", I7, FIND(",", I7, FIND(",", I7, FIND(",", I7, FIND(",", I7, FIND(",", I7, FIND(",", I7, FIND(",", I7, FIND(",", I7) + 1) + 1) + 1) + 1) + 1) + 1) + 1) + 1) + 1, IFERROR(FIND(",", I7, FIND(",", I7, FIND(",", I7, FIND(",", I7, FIND(",", I7, FIND(",", I7, FIND(",", I7, FIND(",", I7, FIND(",", I7) + 1) + 1) + 1) + 1) + 1) + 1) + 1) + 1) - FIND(",", I7, FIND(",", I7, FIND(",", I7, FIND(",", I7, FIND(",", I7, FIND(",", I7, FIND(",", I7, FIND(",", I7) + 1) + 1) + 1) + 1) + 1) + 1) + 1) - 1, LEN(I7)))), "")
A8: 3616842171241DG-A0D-21-18366 | B8: 3616842171241 | C8: DG-A0D-21-18366 | D8: ¡hay que celebrar no importa el motivo! ¿ustedes que piensan mi gente? #losdoscarnales #AfinArte | E8: Los Dos Carnales | G8: AfinArte | H8: =100%-SUM(CatalogTable[[#This Row],[Artist 1 %]],CatalogTable[[#This Row],[Artist 2 %]],CatalogTable[[#This Row],[Artist 3 %]],CatalogTable[[#This Row],[Artist 4 %]],CatalogTable[[#This Row],[Artist 5 %]],CatalogTable[[#This Row],[Artist 6 %]],CatalogTable[[#This Row],[Artist 7 %]],CatalogTable[[#This Row],[Artist 8 %]],CatalogTable[[#This Row],[Artist 9%]]) -> 0.9 | I8: =IF(ISBLANK(E8),"",INDEX(UniqueArtist!B:B, MATCH(E8,UniqueArtist!A:A, 0))) -> Los Dos Carnales | J8: =IFERROR(TRIM(LEFT(I8, IFERROR(FIND(",", I8)-1, LEN(I8)))), "") -> Los Dos Carnales | K8: 0.1 | L8: =IFERROR(TRIM(MID(I8, FIND(",", I8) + 1, IFERROR(FIND(",", I8, FIND(",", I8) + 1) - FIND(",", I8) - 1, LEN(I8)))), "") | N8: =IFERROR(TRIM(MID(I8, FIND(",", I8, FIND(",", I8) + 1) + 1, IFERROR(FIND(",", I8, FIND(",", I8, FIND(",", I8) + 1) + 1) - FIND(",", I8, FIND(",", I8) + 1) - 1, LEN(I8)))), "") | P8: =IFERROR(TRIM(MID(I8, FIND(",", I8, FIND(",", I8, FIND(",", I8) + 1) + 1) + 1, IFERROR(FIND(",", I8, FIND(",", I8, FIND(",", I8, FIND(",", I8) + 1) + 1) + 1) - FIND(",", I8, FIND(",", I8, FIND(",", I8) + 1) + 1) - 1, LEN(I8)))), "") | R8: =IFERROR(TRIM(MID(I8, FIND(",", I8, FIND(",", I8, FIND(",", I8, FIND(",", I8) + 1) + 1) + 1) + 1, IFERROR(FIND(",", I8, FIND(",", I8, FIND(",", I8, FIND(",", I8, FIND(",", I8) + 1) + 1) + 1) + 1) - FIND(",", I8, FIND(",", I8, FIND(",", I8, FIND(",", I8) + 1) + 1) + 1) - 1, LEN(I8)))), "") | T8: =IFERROR(TRIM(MID(I8, FIND(",", I8, FIND(",", I8, FIND(",", I8, FIND(",", I8, FIND(",", I8, FIND(",", I8) + 1) + 1) + 1) + 1) + 1) + 1, IFERROR(FIND(",", I8, FIND(",", I8, FIND(",", I8, FIND(",", I8, FIND(",", I8, FIND(",", I8) + 1) + 1) + 1) + 1) + 1) - FIND(",", I8, FIND(",", I8, FIND(",", I8, FIND(",", I8, FIND(",", I8) + 1) + 1) + 1) + 1) - 1, LEN(I8)))), "") | V8: =IFERROR(TRIM(MID(I8, FIND(",", I8, FIND(",", I8, FIND(",", I8, FIND(",", I8, FIND(",", I8, FIND(",", I8, FIND(",", I8) + 1) + 1) + 1) + 1) + 1) + 1) + 1, IFERROR(FIND(",", I8, FIND(",", I8, FIND(",", I8, FIND(",", I8, FIND(",", I8, FIND(",", I8, FIND(",", I8) + 1) + 1) + 1) + 1) + 1) + 1) - FIND(",", I8, FIND(",", I8, FIND(",", I8, FIND(",", I8, FIND(",", I8, FIND(",", I8) + 1) + 1) + 1) + 1) + 1) - 1, LEN(I8)))), "") | X8: =IFERROR(TRIM(MID(I8, FIND(",", I8, FIND(",", I8, FIND(",", I8, FIND(",", I8, FIND(",", I8, FIND(",", I8, FIND(",", I8, FIND(",", I8) + 1) + 1) + 1) + 1) + 1) + 1) + 1) + 1, IFERROR(FIND(",", I8, FIND(",", I8, FIND(",", I8, FIND(",", I8, FIND(",", I8, FIND(",", I8, FIND(",", I8, FIND(",", I8) + 1) + 1) + 1) + 1) + 1) + 1) + 1) - FIND(",", I8, FIND(",", I8, FIND(",", I8, FIND(",", I8, FIND(",", I8, FIND(",", I8, FIND(",", I8) + 1) + 1) + 1) + 1) + 1) + 1) - 1, LEN(I8)))), "") | Z8: =IFERROR(TRIM(MID(I8, FIND(",", I8, FIND(",", I8, FIND(",", I8, FIND(",", I8, FIND(",", I8, FIND(",", I8, FIND(",", I8, FIND(",", I8, FIND(",", I8) + 1) + 1) + 1) + 1) + 1) + 1) + 1) + 1) + 1, IFERROR(FIND(",", I8, FIND(",", I8, FIND(",", I8, FIND(",", I8, FIND(",", I8, FIND(",", I8, FIND(",", I8, FIND(",", I8, FIND(",", I8) + 1) + 1) + 1) + 1) + 1) + 1) + 1) + 1) - FIND(",", I8, FIND(",", I8, FIND(",", I8, FIND(",", I8, FIND(",", I8, FIND(",", I8, FIND(",", I8, FIND(",", I8) + 1) + 1) + 1) + 1) + 1) + 1) + 1) - 1, LEN(I8)))), "")
A9: 3617053324594FR-S18-22-43262 | B9: 3617053324594 | C9: FR-S18-22-43262 | D9: ¡Like ???????? para Parte ✌???? mi gente! #Tureando #EstadosUnidos #LosDosCarnales #AfinArteMusic | E9: Los Dos Carnales | G9: AfinArte | H9: =100%-SUM(CatalogTable[[#This Row],[Artist 1 %]],CatalogTable[[#This Row],[Artist 2 %]],CatalogTable[[#This Row],[Artist 3 %]],CatalogTable[[#This Row],[Artist 4 %]],CatalogTable[[#This Row],[Artist 5 %]],CatalogTable[[#This Row],[Artist 6 %]],CatalogTable[[#This Row],[Artist 7 %]],CatalogTable[[#This Row],[Artist 8 %]],CatalogTable[[#This Row],[Artist 9%]]) -> 0.9 | I9: =IF(ISBLANK(E9),"",INDEX(UniqueArtist!B:B, MATCH(E9,UniqueArtist!A:A, 0))) -> Los Dos Carnales | J9: =IFERROR(TRIM(LEFT(I9, IFERROR(FIND(",", I9)-1, LEN(I9)))), "") -> Los Dos Carnales | K9: 0.1 | L9: =IFERROR(TRIM(MID(I9, FIND(",", I9) + 1, IFERROR(FIND(",", I9, FIND(",", I9) + 1) - FIND(",", I9) - 1, LEN(I9)))), "") | N9: =IFERROR(TRIM(MID(I9, FIND(",", I9, FIND(",", I9) + 1) + 1, IFERROR(FIND(",", I9, FIND(",", I9, FIND(",", I9) + 1) + 1) - FIND(",", I9, FIND(",", I9) + 1) - 1, LEN(I9)))), "") | P9: =IFERROR(TRIM(MID(I9, FIND(",", I9, FIND(",", I9, FIND(",", I9) + 1) + 1) + 1, IFERROR(FIND(",", I9, FIND(",", I9, FIND(",", I9, FIND(",", I9) + 1) + 1) + 1) - FIND(",", I9, FIND(",", I9, FIND(",", I9) + 1) + 1) - 1, LEN(I9)))), "") | R9: =IFERROR(TRIM(MID(I9, FIND(",", I9, FIND(",", I9, FIND(",", I9, FIND(",", I9) + 1) + 1) + 1) + 1, IFERROR(FIND(",", I9, FIND(",", I9, FIND(",", I9, FIND(",", I9, FIND(",", I9) + 1) + 1) + 1) + 1) - FIND(",", I9, FIND(",", I9, FIND(",", I9, FIND(",", I9) + 1) + 1) + 1) - 1, LEN(I9)))), "") | T9: =IFERROR(TRIM(MID(I9, FIND(",", I9, FIND(",", I9, FIND(",", I9, FIND(",", I9, FIND(",", I9, FIND(",", I9) + 1) + 1) + 1) + 1) + 1) + 1, IFERROR(FIND(",", I9, FIND(",", I9, FIND(",", I9, FIND(",", I9, FIND(",", I9, FIND(",", I9) + 1) + 1) + 1) + 1) + 1) - FIND(",", I9, FIND(",", I9, FIND(",", I9, FIND(",", I9, FIND(",", I9) + 1) + 1) + 1) + 1) - 1, LEN(I9)))), "") | V9: =IFERROR(TRIM(MID(I9, FIND(",", I9, FIND(",", I9, FIND(",", I9, FIND(",", I9, FIND(",", I9, FIND(",", I9, FIND(",", I9) + 1) + 1) + 1) + 1) + 1) + 1) + 1, IFERROR(FIND(",", I9, FIND(",", I9, FIND(",", I9, FIND(",", I9, FIND(",", I9, FIND(",", I9, FIND(",", I9) + 1) + 1) + 1) + 1) + 1) + 1) - FIND(",", I9, FIND(",", I9, FIND(",", I9, FIND(",", I9, FIND(",", I9, FIND(",", I9) + 1) + 1) + 1) + 1) + 1) - 1, LEN(I9)))), "") | X9: =IFERROR(TRIM(MID(I9, FIND(",", I9, FIND(",", I9, FIND(",", I9, FIND(",", I9, FIND(",", I9, FIND(",", I9, FIND(",", I9, FIND(",", I9) + 1) + 1) + 1) + 1) + 1) + 1) + 1) + 1, IFERROR(FIND(",", I9, FIND(",", I9, FIND(",", I9, FIND(",", I9, FIND(",", I9, FIND(",", I9, FIND(",", I9, FIND(",", I9) + 1) + 1) + 1) + 1) + 1) + 1) + 1) - FIND(",", I9, FIND(",", I9, FIND(",", I9, FIND(",", I9, FIND(",", I9, FIND(",", I9, FIND(",", I9) + 1) + 1) + 1) + 1) + 1) + 1) - 1, LEN(I9)))), "") | Z9: =IFERROR(TRIM(MID(I9, FIND(",", I9, FIND(",", I9, FIND(",", I9, FIND(",", I9, FIND(",", I9, FIND(",", I9, FIND(",", I9, FIND(",", I9, FIND(",", I9) + 1) + 1) + 1) + 1) + 1) + 1) + 1) + 1) + 1, IFERROR(FIND(",", I9, FIND(",", I9, FIND(",", I9, FIND(",", I9, FIND(",", I9, FIND(",", I9, FIND(",", I9, FIND(",", I9, FIND(",", I9) + 1) + 1) + 1) + 1) + 1) + 1) + 1) + 1) - FIND(",", I9, FIND(",", I9, FIND(",", I9, FIND(",", I9, FIND(",", I9, FIND(",", I9, FIND(",", I9, FIND(",", I9) + 1) + 1) + 1) + 1) + 1) + 1) + 1) - 1, LEN(I9)))), "")
A10: 3617052285391FR-S18-22-03373 | B10: 3617052285391 | C10: FR-S18-22-03373 | D10: ¡Los Quiero #Tijuana! @Adriana Ríos #AfinArteMusic #FeriaDeTijuana | E10: Adriana Ríos | G10: AfinArte | H10: =100%-SUM(CatalogTable[[#This Row],[Artist 1 %]],CatalogTable[[#This Row],[Artist 2 %]],CatalogTable[[#This Row],[Artist 3 %]],CatalogTable[[#This Row],[Artist 4 %]],CatalogTable[[#This Row],[Artist 5 %]],CatalogTable[[#This Row],[Artist 6 %]],CatalogTable[[#This Row],[Artist 7 %]],CatalogTable[[#This Row],[Artist 8 %]],CatalogTable[[#This Row],[Artist 9%]]) -> 0.9 | I10: =IF(ISBLANK(E10),"",INDEX(UniqueArtist!B:B, MATCH(E10,UniqueArtist!A:A, 0))) -> Adriana Rios | J10: =IFERROR(TRIM(LEFT(I10, IFERROR(FIND(",", I10)-1, LEN(I10)))), "") -> Adriana Rios | K10: 0.1 | L10: =IFERROR(TRIM(MID(I10, FIND(",", I10) + 1, IFERROR(FIND(",", I10, FIND(",", I10) + 1) - FIND(",", I10) - 1, LEN(I10)))), "") | N10: =IFERROR(TRIM(MID(I10, FIND(",", I10, FIND(",", I10) + 1) + 1, IFERROR(FIND(",", I10, FIND(",", I10, FIND(",", I10) + 1) + 1) - FIND(",", I10, FIND(",", I10) + 1) - 1, LEN(I10)))), "") | P10: =IFERROR(TRIM(MID(I10, FIND(",", I10, FIND(",", I10, FIND(",", I10) + 1) + 1) + 1, IFERROR(FIND(",", I10, FIND(",", I10, FIND(",", I10, FIND(",", I10) + 1) + 1) + 1) - FIND(",", I10, FIND(",", I10, FIND(",", I10) + 1) + 1) - 1, LEN(I10)))), "") | R10: =IFERROR(TRIM(MID(I10, FIND(",", I10, FIND(",", I10, FIND(",", I10, FIND(",", I10) + 1) + 1) + 1) + 1, IFERROR(FIND(",", I10, FIND(",", I10, FIND(",", I10, FIND(",", I10, FIND(",", I10) + 1) + 1) + 1) + 1) - FIND(",", I10, FIND(",", I10, FIND(",", I10, FIND(",", I10) + 1) + 1) + 1) - 1, LEN(I10)))), "") | T10: =IFERROR(TRIM(MID(I10, FIND(",", I10, FIND(",", I10, FIND(",", I10, FIND(",", I10, FIND(",", I10, FIND(",", I10) + 1) + 1) + 1) + 1) + 1) + 1, IFERROR(FIND(",", I10, FIND(",", I10, FIND(",", I10, FIND(",", I10, FIND(",", I10, FIND(",", I10) + 1) + 1) + 1) + 1) + 1) - FIND(",", I10, FIND(",", I10, FIND(",", I10, FIND(",", I10, FIND(",", I10) + 1) + 1) + 1) + 1) - 1, LEN(I10)))), "") | V10: =IFERROR(TRIM(MID(I10, FIND(",", I10, FIND(",", I10, FIND(",", I10, FIND(",", I10, FIND(",", I10, FIND(",", I10, FIND(",", I10) + 1) + 1) + 1) + 1) + 1) + 1) + 1, IFERROR(FIND(",", I10, FIND(",", I10, FIND(",", I10, FIND(",", I10, FIND(",", I10, FIND(",", I10, FIND(",", I10) + 1) + 1) + 1) + 1) + 1) + 1) - FIND(",", I10, FIND(",", I10, FIND(",", I10, FIND(",", I10, FIND(",", I10, FIND(",", I10) + 1) + 1) + 1) + 1) + 1) - 1, LEN(I10)))), "") | X10: =IFERROR(TRIM(MID(I10, FIND(",", I10, FIND(",", I10, FIND(",", I10, FIND(",", I10, FIND(",", I10, FIND(",", I10, FIND(",", I10, FIND(",", I10) + 1) + 1) + 1) + 1) + 1) + 1) + 1) + 1, IFERROR(FIND(",", I10, FIND(",", I10, FIND(",", I10, FIND(",", I10, FIND(",", I10, FIND(",", I10, FIND(",", I10, FIND(",", I10) + 1) + 1) + 1) + 1) + 1) + 1) + 1) - FIND(",", I10, FIND(",", I10, FIND(",", I10, FIND(",", I10, FIND(",", I10, FIND(",", I10, FIND(",", I10) + 1) + 1) + 1) + 1) + 1) + 1) - 1, LEN(I10)))), "") | Z10: =IFERROR(TRIM(MID(I10, FIND(",", I10, FIND(",", I10, FIND(",", I10, FIND(",", I10, FIND(",", I10, FIND(",", I10, FIND(",", I10, FIND(",", I10, FIND(",", I10) + 1) + 1) + 1) + 1) + 1) + 1) + 1) + 1) + 1, IFERROR(FIND(",", I10, FIND(",", I10, FIND(",", I10, FIND(",", I10, FIND(",", I10, FIND(",", I10, FIND(",", I10, FIND(",", I10, FIND(",", I10) + 1) + 1) + 1) + 1) + 1) + 1) + 1) + 1) - FIND(",", I10, FIND(",", I10, FIND(",", I10, FIND(",", I10, FIND(",", I10, FIND(",", I10, FIND(",", I10, FIND(",", I10) + 1) + 1) + 1) + 1) + 1) + 1) + 1) - 1, LEN(I10)))), "")
A11: 3617057125401FR-W24-23-75325 | B11: 3617057125401 | C11: FR-W24-23-75325 | D11: ¡No! El Dinero a mi no me cambio ???????? #ElFantasma #ElSelectivo #Shorts #ShortsVideo #AfinArte | E11: El Fantasma | G11: AfinArte | H11: =100%-SUM(CatalogTable[[#This Row],[Artist 1 %]],CatalogTable[[#This Row],[Artist 2 %]],CatalogTable[[#This Row],[Artist 3 %]],CatalogTable[[#This Row],[Artist 4 %]],CatalogTable[[#This Row],[Artist 5 %]],CatalogTable[[#This Row],[Artist 6 %]],CatalogTable[[#This Row],[Artist 7 %]],CatalogTable[[#This Row],[Artist 8 %]],CatalogTable[[#This Row],[Artist 9%]]) -> 0.65 | I11: =IF(ISBLANK(E11),"",INDEX(UniqueArtist!B:B, MATCH(E11,UniqueArtist!A:A, 0))) -> El Fantasma | J11: =IFERROR(TRIM(LEFT(I11, IFERROR(FIND(",", I11)-1, LEN(I11)))), "") -> El Fantasma | K11: 0.35 | L11: =IFERROR(TRIM(MID(I11, FIND(",", I11) + 1, IFERROR(FIND(",", I11, FIND(",", I11) + 1) - FIND(",", I11) - 1, LEN(I11)))), "") | N11: =IFERROR(TRIM(MID(I11, FIND(",", I11, FIND(",", I11) + 1) + 1, IFERROR(FIND(",", I11, FIND(",", I11, FIND(",", I11) + 1) + 1) - FIND(",", I11, FIND(",", I11) + 1) - 1, LEN(I11)))), "") | P11: =IFERROR(TRIM(MID(I11, FIND(",", I11, FIND(",", I11, FIND(",", I11) + 1) + 1) + 1, IFERROR(FIND(",", I11, FIND(",", I11, FIND(",", I11, FIND(",", I11) + 1) + 1) + 1) - FIND(",", I11, FIND(",", I11, FIND(",", I11) + 1) + 1) - 1, LEN(I11)))), "") | R11: =IFERROR(TRIM(MID(I11, FIND(",", I11, FIND(",", I11, FIND(",", I11, FIND(",", I11) + 1) + 1) + 1) + 1, IFERROR(FIND(",", I11, FIND(",", I11, FIND(",", I11, FIND(",", I11, FIND(",", I11) + 1) + 1) + 1) + 1) - FIND(",", I11, FIND(",", I11, FIND(",", I11, FIND(",", I11) + 1) + 1) + 1) - 1, LEN(I11)))), "") | T11: =IFERROR(TRIM(MID(I11, FIND(",", I11, FIND(",", I11, FIND(",", I11, FIND(",", I11, FIND(",", I11, FIND(",", I11) + 1) + 1) + 1) + 1) + 1) + 1, IFERROR(FIND(",", I11, FIND(",", I11, FIND(",", I11, FIND(",", I11, FIND(",", I11, FIND(",", I11) + 1) + 1) + 1) + 1) + 1) - FIND(",", I11, FIND(",", I11, FIND(",", I11, FIND(",", I11, FIND(",", I11) + 1) + 1) + 1) + 1) - 1, LEN(I11)))), "") | V11: =IFERROR(TRIM(MID(I11, FIND(",", I11, FIND(",", I11, FIND(",", I11, FIND(",", I11, FIND(",", I11, FIND(",", I11, FIND(",", I11) + 1) + 1) + 1) + 1) + 1) + 1) + 1, IFERROR(FIND(",", I11, FIND(",", I11, FIND(",", I11, FIND(",", I11, FIND(",", I11, FIND(",", I11, FIND(",", I11) + 1) + 1) + 1) + 1) + 1) + 1) - FIND(",", I11, FIND(",", I11, FIND(",", I11, FIND(",", I11, FIND(",", I11, FIND(",", I11) + 1) + 1) + 1) + 1) + 1) - 1, LEN(I11)))), "") | X11: =IFERROR(TRIM(MID(I11, FIND(",", I11, FIND(",", I11, FIND(",", I11, FIND(",", I11, FIND(",", I11, FIND(",", I11, FIND(",", I11, FIND(",", I11) + 1) + 1) + 1) + 1) + 1) + 1) + 1) + 1, IFERROR(FIND(",", I11, FIND(",", I11, FIND(",", I11, FIND(",", I11, FIND(",", I11, FIND(",", I11, FIND(",", I11, FIND(",", I11) + 1) + 1) + 1) + 1) + 1) + 1) + 1) - FIND(",", I11, FIND(",", I11, FIND(",", I11, FIND(",", I11, FIND(",", I11, FIND(",", I11, FIND(",", I11) + 1) + 1) + 1) + 1) + 1) + 1) - 1, LEN(I11)))), "") | Z11: =IFERROR(TRIM(MID(I11, FIND(",", I11, FIND(",", I11, FIND(",", I11, FIND(",", I11, FIND(",", I11, FIND(",", I11, FIND(",", I11, FIND(",", I11, FIND(",", I11) + 1) + 1) + 1) + 1) + 1) + 1) + 1) + 1) + 1, IFERROR(FIND(",", I11, FIND(",", I11, FIND(",", I11, FIND(",", I11, FIND(",", I11, FIND(",", I11, FIND(",", I11, FIND(",", I11, FIND(",", I11) + 1) + 1) + 1) + 1) + 1) + 1) + 1) + 1) - FIND(",", I11, FIND(",", I11, FIND(",", I11, FIND(",", I11, FIND(",", I11, FIND(",", I11, FIND(",", I11, FIND(",", I11) + 1) + 1) + 1) + 1) + 1) + 1) + 1) - 1, LEN(I11)))), "")
A12: 3617052596404FR-S18-22-14503 | B12: 3617052596404 | C12: FR-S18-22-14503 | D12: ¡Nos encontramos a #SpiderMan y #ElChapulinColorado en NY! @AfinArte Music #LosDosCarnales #NYC | E12: Los Dos Carnales | G12: AfinArte | H12: =100%-SUM(CatalogTable[[#This Row],[Artist 1 %]],CatalogTable[[#This Row],[Artist 2 %]],CatalogTable[[#This Row],[Artist 3 %]],CatalogTable[[#This Row],[Artist 4 %]],CatalogTable[[#This Row],[Artist 5 %]],CatalogTable[[#This Row],[Artist 6 %]],CatalogTable[[#This Row],[Artist 7 %]],CatalogTable[[#This Row],[Artist 8 %]],CatalogTable[[#This Row],[Artist 9%]]) -> 0.9 | I12: =IF(ISBLANK(E12),"",INDEX(UniqueArtist!B:B, MATCH(E12,UniqueArtist!A:A, 0))) -> Los Dos Carnales | J12: =IFERROR(TRIM(LEFT(I12, IFERROR(FIND(",", I12)-1, LEN(I12)))), "") -> Los Dos Carnales | K12: 0.1 | L12: =IFERROR(TRIM(MID(I12, FIND(",", I12) + 1, IFERROR(FIND(",", I12, FIND(",", I12) + 1) - FIND(",", I12) - 1, LEN(I12)))), "") | N12: =IFERROR(TRIM(MID(I12, FIND(",", I12, FIND(",", I12) + 1) + 1, IFERROR(FIND(",", I12, FIND(",", I12, FIND(",", I12) + 1) + 1) - FIND(",", I12, FIND(",", I12) + 1) - 1, LEN(I12)))), "") | P12: =IFERROR(TRIM(MID(I12, FIND(",", I12, FIND(",", I12, FIND(",", I12) + 1) + 1) + 1, IFERROR(FIND(",", I12, FIND(",", I12, FIND(",", I12, FIND(",", I12) + 1) + 1) + 1) - FIND(",", I12, FIND(",", I12, FIND(",", I12) + 1) + 1) - 1, LEN(I12)))), "") | R12: =IFERROR(TRIM(MID(I12, FIND(",", I12, FIND(",", I12, FIND(",", I12, FIND(",", I12) + 1) + 1) + 1) + 1, IFERROR(FIND(",", I12, FIND(",", I12, FIND(",", I12, FIND(",", I12, FIND(",", I12) + 1) + 1) + 1) + 1) - FIND(",", I12, FIND(",", I12, FIND(",", I12, FIND(",", I12) + 1) + 1) + 1) - 1, LEN(I12)))), "") | T12: =IFERROR(TRIM(MID(I12, FIND(",", I12, FIND(",", I12, FIND(",", I12, FIND(",", I12, FIND(",", I12, FIND(",", I12) + 1) + 1) + 1) + 1) + 1) + 1, IFERROR(FIND(",", I12, FIND(",", I12, FIND(",", I12, FIND(",", I12, FIND(",", I12, FIND(",", I12) + 1) + 1) + 1) + 1) + 1) - FIND(",", I12, FIND(",", I12, FIND(",", I12, FIND(",", I12, FIND(",", I12) + 1) + 1) + 1) + 1) - 1, LEN(I12)))), "") | V12: =IFERROR(TRIM(MID(I12, FIND(",", I12, FIND(",", I12, FIND(",", I12, FIND(",", I12, FIND(",", I12, FIND(",", I12, FIND(",", I12) + 1) + 1) + 1) + 1) + 1) + 1) + 1, IFERROR(FIND(",", I12, FIND(",", I12, FIND(",", I12, FIND(",", I12, FIND(",", I12, FIND(",", I12, FIND(",", I12) + 1) + 1) + 1) + 1) + 1) + 1) - FIND(",", I12, FIND(",", I12, FIND(",", I12, FIND(",", I12, FIND(",", I12, FIND(",", I12) + 1) + 1) + 1) + 1) + 1) - 1, LEN(I12)))), "") | X12: =IFERROR(TRIM(MID(I12, FIND(",", I12, FIND(",", I12, FIND(",", I12, FIND(",", I12, FIND(",", I12, FIND(",", I12, FIND(",", I12, FIND(",", I12) + 1) + 1) + 1) + 1) + 1) + 1) + 1) + 1, IFERROR(FIND(",", I12, FIND(",", I12, FIND(",", I12, FIND(",", I12, FIND(",", I12, FIND(",", I12, FIND(",", I12, FIND(",", I12) + 1) + 1) + 1) + 1) + 1) + 1) + 1) - FIND(",", I12, FIND(",", I12, FIND(",", I12, FIND(",", I12, FIND(",", I12, FIND(",", I12, FIND(",", I12) + 1) + 1) + 1) + 1) + 1) + 1) - 1, LEN(I12)))), "") | Z12: =IFERROR(TRIM(MID(I12, FIND(",", I12, FIND(",", I12, FIND(",", I12, FIND(",", I12, FIND(",", I12, FIND(",", I12, FIND(",", I12, FIND(",", I12, FIND(",", I12) + 1) + 1) + 1) + 1) + 1) + 1) + 1) + 1) + 1, IFERROR(FIND(",", I12, FIND(",", I12, FIND(",", I12, FIND(",", I12, FIND(",", I12, FIND(",", I12, FIND(",", I12, FIND(",", I12, FIND(",", I12) + 1) + 1) + 1) + 1) + 1) + 1) + 1) + 1) - FIND(",", I12, FIND(",", I12, FIND(",", I12, FIND(",", I12, FIND(",", I12, FIND(",", I12, FIND(",", I12, FIND(",", I12) + 1) + 1) + 1) + 1) + 1) + 1) + 1) - 1, LEN(I12)))), "")
A13: 3617381804102DG-A0J-23-90371 | B13: 3617381804102 | C13: DG-A0J-23-90371 | D13: ¡Quedan 2 señores!😮 #VozDeMando #Phoenix #Shorts #Navidad | E13: Voz De Mando | G13: AfinArte | H13: =100%-SUM(CatalogTable[[#This Row],[Artist 1 %]],CatalogTable[[#This Row],[Artist 2 %]],CatalogTable[[#This Row],[Artist 3 %]],CatalogTable[[#This Row],[Artist 4 %]],CatalogTable[[#This Row],[Artist 5 %]],CatalogTable[[#This Row],[Artist 6 %]],CatalogTable[[#This Row],[Artist 7 %]],CatalogTable[[#This Row],[Artist 8 %]],CatalogTable[[#This Row],[Artist 9%]]) -> 0 | I13: =IF(ISBLANK(E13),"",INDEX(UniqueArtist!B:B, MATCH(E13,UniqueArtist!A:A, 0))) -> Voz de Mando | J13: =IFERROR(TRIM(LEFT(I13, IFERROR(FIND(",", I13)-1, LEN(I13)))), "") -> Voz de Mando | K13: 1 | L13: =IFERROR(TRIM(MID(I13, FIND(",", I13) + 1, IFERROR(FIND(",", I13, FIND(",", I13) + 1) - FIND(",", I13) - 1, LEN(I13)))), "") | N13: =IFERROR(TRIM(MID(I13, FIND(",", I13, FIND(",", I13) + 1) + 1, IFERROR(FIND(",", I13, FIND(",", I13, FIND(",", I13) + 1) + 1) - FIND(",", I13, FIND(",", I13) + 1) - 1, LEN(I13)))), "") | P13: =IFERROR(TRIM(MID(I13, FIND(",", I13, FIND(",", I13, FIND(",", I13) + 1) + 1) + 1, IFERROR(FIND(",", I13, FIND(",", I13, FIND(",", I13, FIND(",", I13) + 1) + 1) + 1) - FIND(",", I13, FIND(",", I13, FIND(",", I13) + 1) + 1) - 1, LEN(I13)))), "") | R13: =IFERROR(TRIM(MID(I13, FIND(",", I13, FIND(",", I13, FIND(",", I13, FIND(",", I13) + 1) + 1) + 1) + 1, IFERROR(FIND(",", I13, FIND(",", I13, FIND(",", I13, FIND(",", I13, FIND(",", I13) + 1) + 1) + 1) + 1) - FIND(",", I13, FIND(",", I13, FIND(",", I13, FIND(",", I13) + 1) + 1) + 1) - 1, LEN(I13)))), "") | T13: =IFERROR(TRIM(MID(I13, FIND(",", I13, FIND(",", I13, FIND(",", I13, FIND(",", I13, FIND(",", I13, FIND(",", I13) + 1) + 1) + 1) + 1) + 1) + 1, IFERROR(FIND(",", I13, FIND(",", I13, FIND(",", I13, FIND(",", I13, FIND(",", I13, FIND(",", I13) + 1) + 1) + 1) + 1) + 1) - FIND(",", I13, FIND(",", I13, FIND(",", I13, FIND(",", I13, FIND(",", I13) + 1) + 1) + 1) + 1) - 1, LEN(I13)))), "") | V13: =IFERROR(TRIM(MID(I13, FIND(",", I13, FIND(",", I13, FIND(",", I13, FIND(",", I13, FIND(",", I13, FIND(",", I13, FIND(",", I13) + 1) + 1) + 1) + 1) + 1) + 1) + 1, IFERROR(FIND(",", I13, FIND(",", I13, FIND(",", I13, FIND(",", I13, FIND(",", I13, FIND(",", I13, FIND(",", I13) + 1) + 1) + 1) + 1) + 1) + 1) - FIND(",", I13, FIND(",", I13, FIND(",", I13, FIND(",", I13, FIND(",", I13, FIND(",", I13) + 1) + 1) + 1) + 1) + 1) - 1, LEN(I13)))), "") | X13: =IFERROR(TRIM(MID(I13, FIND(",", I13, FIND(",", I13, FIND(",", I13, FIND(",", I13, FIND(",", I13, FIND(",", I13, FIND(",", I13, FIND(",", I13) + 1) + 1) + 1) + 1) + 1) + 1) + 1) + 1, IFERROR(FIND(",", I13, FIND(",", I13, FIND(",", I13, FIND(",", I13, FIND(",", I13, FIND(",", I13, FIND(",", I13, FIND(",", I13) + 1) + 1) + 1) + 1) + 1) + 1) + 1) - FIND(",", I13, FIND(",", I13, FIND(",", I13, FIND(",", I13, FIND(",", I13, FIND(",", I13, FIND(",", I13) + 1) + 1) + 1) + 1) + 1) + 1) - 1, LEN(I13)))), "") | Z13: =IFERROR(TRIM(MID(I13, FIND(",", I13, FIND(",", I13, FIND(",", I13, FIND(",", I13, FIND(",", I13, FIND(",", I13, FIND(",", I13, FIND(",", I13, FIND(",", I13) + 1) + 1) + 1) + 1) + 1) + 1) + 1) + 1) + 1, IFERROR(FIND(",", I13, FIND(",", I13, FIND(",", I13, FIND(",", I13, FIND(",", I13, FIND(",", I13, FIND(",", I13, FIND(",", I13, FIND(",", I13) + 1) + 1) + 1) + 1) + 1) + 1) + 1) + 1) - FIND(",", I13, FIND(",", I13, FIND(",", I13, FIND(",", I13, FIND(",", I13, FIND(",", I13, FIND(",", I13, FIND(",", I13) + 1) + 1) + 1) + 1) + 1) + 1) + 1) - 1, LEN(I13)))), "")
A14: 3617058135164FR-W77-23-07901 | B14: 3617058135164 | C14: FR-W77-23-07901 | D14: ¡TE REGALAMOS UN TRAJE! ~~~~~~#Shorts #shortsvideo #ElFantasma | E14: El Fantasma | G14: AfinArte | H14: =100%-SUM(CatalogTable[[#This Row],[Artist 1 %]],CatalogTable[[#This Row],[Artist 2 %]],CatalogTable[[#This Row],[Artist 3 %]],CatalogTable[[#This Row],[Artist 4 %]],CatalogTable[[#This Row],[Artist 5 %]],CatalogTable[[#This Row],[Artist 6 %]],CatalogTable[[#This Row],[Artist 7 %]],CatalogTable[[#This Row],[Artist 8 %]],CatalogTable[[#This Row],[Artist 9%]]) -> 0.65 | I14: =IF(ISBLANK(E14),"",INDEX(UniqueArtist!B:B, MATCH(E14,UniqueArtist!A:A, 0))) -> El Fantasma | J14: =IFERROR(TRIM(LEFT(I14, IFERROR(FIND(",", I14)-1, LEN(I14)))), "") -> El Fantasma | K14: 0.35 | L14: =IFERROR(TRIM(MID(I14, FIND(",", I14) + 1, IFERROR(FIND(",", I14, FIND(",", I14) + 1) - FIND(",", I14) - 1, LEN(I14)))), "") | N14: =IFERROR(TRIM(MID(I14, FIND(",", I14, FIND(",", I14) + 1) + 1, IFERROR(FIND(",", I14, FIND(",", I14, FIND(",", I14) + 1) + 1) - FIND(",", I14, FIND(",", I14) + 1) - 1, LEN(I14)))), "") | P14: =IFERROR(TRIM(MID(I14, FIND(",", I14, FIND(",", I14, FIND(",", I14) + 1) + 1) + 1, IFERROR(FIND(",", I14, FIND(",", I14, FIND(",", I14, FIND(",", I14) + 1) + 1) + 1) - FIND(",", I14, FIND(",", I14, FIND(",", I14) + 1) + 1) - 1, LEN(I14)))), "") | R14: =IFERROR(TRIM(MID(I14, FIND(",", I14, FIND(",", I14, FIND(",", I14, FIND(",", I14) + 1) + 1) + 1) + 1, IFERROR(FIND(",", I14, FIND(",", I14, FIND(",", I14, FIND(",", I14, FIND(",", I14) + 1) + 1) + 1) + 1) - FIND(",", I14, FIND(",", I14, FIND(",", I14, FIND(",", I14) + 1) + 1) + 1) - 1, LEN(I14)))), "") | T14: =IFERROR(TRIM(MID(I14, FIND(",", I14, FIND(",", I14, FIND(",", I14, FIND(",", I14, FIND(",", I14, FIND(",", I14) + 1) + 1) + 1) + 1) + 1) + 1, IFERROR(FIND(",", I14, FIND(",", I14, FIND(",", I14, FIND(",", I14, FIND(",", I14, FIND(",", I14) + 1) + 1) + 1) + 1) + 1) - FIND(",", I14, FIND(",", I14, FIND(",", I14, FIND(",", I14, FIND(",", I14) + 1) + 1) + 1) + 1) - 1, LEN(I14)))), "") | V14: =IFERROR(TRIM(MID(I14, FIND(",", I14, FIND(",", I14, FIND(",", I14, FIND(",", I14, FIND(",", I14, FIND(",", I14, FIND(",", I14) + 1) + 1) + 1) + 1) + 1) + 1) + 1, IFERROR(FIND(",", I14, FIND(",", I14, FIND(",", I14, FIND(",", I14, FIND(",", I14, FIND(",", I14, FIND(",", I14) + 1) + 1) + 1) + 1) + 1) + 1) - FIND(",", I14, FIND(",", I14, FIND(",", I14, FIND(",", I14, FIND(",", I14, FIND(",", I14) + 1) + 1) + 1) + 1) + 1) - 1, LEN(I14)))), "") | X14: =IFERROR(TRIM(MID(I14, FIND(",", I14, FIND(",", I14, FIND(",", I14, FIND(",", I14, FIND(",", I14, FIND(",", I14, FIND(",", I14, FIND(",", I14) + 1) + 1) + 1) + 1) + 1) + 1) + 1) + 1, IFERROR(FIND(",", I14, FIND(",", I14, FIND(",", I14, FIND(",", I14, FIND(",", I14, FIND(",", I14, FIND(",", I14, FIND(",", I14) + 1) + 1) + 1) + 1) + 1) + 1) + 1) - FIND(",", I14, FIND(",", I14, FIND(",", I14, FIND(",", I14, FIND(",", I14, FIND(",", I14, FIND(",", I14) + 1) + 1) + 1) + 1) + 1) + 1) - 1, LEN(I14)))), "") | Z14: =IFERROR(TRIM(MID(I14, FIND(",", I14, FIND(",", I14, FIND(",", I14, FIND(",", I14, FIND(",", I14, FIND(",", I14, FIND(",", I14, FIND(",", I14, FIND(",", I14) + 1) + 1) + 1) + 1) + 1) + 1) + 1) + 1) + 1, IFERROR(FIND(",", I14, FIND(",", I14, FIND(",", I14, FIND(",", I14, FIND(",", I14, FIND(",", I14, FIND(",", I14, FIND(",", I14, FIND(",", I14) + 1) + 1) + 1) + 1) + 1) + 1) + 1) + 1) - FIND(",", I14, FIND(",", I14, FIND(",", I14, FIND(",", I14, FIND(",", I14, FIND(",", I14, FIND(",", I14, FIND(",", I14) + 1) + 1) + 1) + 1) + 1) + 1) + 1) - 1, LEN(I14)))), "")
... A87: 3616841324990DG-A0C-21-88467 | B87: 3616841324990 | C87: DG-A0C-21-88467 | D87: ¿y los 15mil dólares? a lucir el tobillo raza | E87: El Fantasma | G87: AfinArte | H87: =100%-SUM(CatalogTable[[#This Row],[Artist 1 %]],CatalogTable[[#This Row],[Artist 2 %]],CatalogTable[[#This Row],[Artist 3 %]],CatalogTable[[#This Row],[Artist 4 %]],CatalogTable[[#This Row],[Artist 5 %]],CatalogTable[[#This Row],[Artist 6 %]],CatalogTable[[#This Row],[Artist 7 %]],CatalogTable[[#This Row],[Artist 8 %]],CatalogTable[[#This Row],[Artist 9%]]) -> 0.65 | I87: =IF(ISBLANK(E87),"",INDEX(UniqueArtist!B:B, MATCH(E87,UniqueArtist!A:A, 0))) -> El Fantasma | J87: =IFERROR(TRIM(LEFT(I87, IFERROR(FIND(",", I87)-1, LEN(I87)))), "") -> El Fantasma | K87: 0.35 | L87: =IFERROR(TRIM(MID(I87, FIND(",", I87) + 1, IFERROR(FIND(",", I87, FIND(",", I87) + 1) - FIND(",", I87) - 1, LEN(I87)))), "") | N87: =IFERROR(TRIM(MID(I87, FIND(",", I87, FIND(",", I87) + 1) + 1, IFERROR(FIND(",", I87, FIND(",", I87, FIND(",", I87) + 1) + 1) - FIND(",", I87, FIND(",", I87) + 1) - 1, LEN(I87)))), "") | P87: =IFERROR(TRIM(MID(I87, FIND(",", I87, FIND(",", I87, FIND(",", I87) + 1) + 1) + 1, IFERROR(FIND(",", I87, FIND(",", I87, FIND(",", I87, FIND(",", I87) + 1) + 1) + 1) - FIND(",", I87, FIND(",", I87, FIND(",", I87) + 1) + 1) - 1, LEN(I87)))), "") | R87: =IFERROR(TRIM(MID(I87, FIND(",", I87, FIND(",", I87, FIND(",", I87, FIND(",", I87) + 1) + 1) + 1) + 1, IFERROR(FIND(",", I87, FIND(",", I87, FIND(",", I87, FIND(",", I87, FIND(",", I87) + 1) + 1) + 1) + 1) - FIND(",", I87, FIND(",", I87, FIND(",", I87, FIND(",", I87) + 1) + 1) + 1) - 1, LEN(I87)))), "") | T87: =IFERROR(TRIM(MID(I87, FIND(",", I87, FIND(",", I87, FIND(",", I87, FIND(",", I87, FIND(",", I87, FIND(",", I87) + 1) + 1) + 1) + 1) + 1) + 1, IFERROR(FIND(",", I87, FIND(",", I87, FIND(",", I87, FIND(",", I87, FIND(",", I87, FIND(",", I87) + 1) + 1) + 1) + 1) + 1) - FIND(",", I87, FIND(",", I87, FIND(",", I87, FIND(",", I87, FIND(",", I87) + 1) + 1) + 1) + 1) - 1, LEN(I87)))), "") | V87: =IFERROR(TRIM(MID(I87, FIND(",", I87, FIND(",", I87, FIND(",", I87, FIND(",", I87, FIND(",", I87, FIND(",", I87, FIND(",", I87) + 1) + 1) + 1) + 1) + 1) + 1) + 1, IFERROR(FIND(",", I87, FIND(",", I87, FIND(",", I87, FIND(",", I87, FIND(",", I87, FIND(",", I87, FIND(",", I87) + 1) + 1) + 1) + 1) + 1) + 1) - FIND(",", I87, FIND(",", I87, FIND(",", I87, FIND(",", I87, FIND(",", I87, FIND(",", I87) + 1) + 1) + 1) + 1) + 1) - 1, LEN(I87)))), "") | X87: =IFERROR(TRIM(MID(I87, FIND(",", I87, FIND(",", I87, FIND(",", I87, FIND(",", I87, FIND(",", I87, FIND(",", I87, FIND(",", I87, FIND(",", I87) + 1) + 1) + 1) + 1) + 1) + 1) + 1) + 1, IFERROR(FIND(",", I87, FIND(",", I87, FIND(",", I87, FIND(",", I87, FIND(",", I87, FIND(",", I87, FIND(",", I87, FIND(",", I87) + 1) + 1) + 1) + 1) + 1) + 1) + 1) - FIND(",", I87, FIND(",", I87, FIND(",", I87, FIND(",", I87, FIND(",", I87, FIND(",", I87, FIND(",", I87) + 1) + 1) + 1) + 1) + 1) + 1) - 1, LEN(I87)))), "") | Z87: =IFERROR(TRIM(MID(I87, FIND(",", I87, FIND(",", I87, FIND(",", I87, FIND(",", I87, FIND(",", I87, FIND(",", I87, FIND(",", I87, FIND(",", I87, FIND(",", I87) + 1) + 1) + 1) + 1) + 1) + 1) + 1) + 1) + 1, IFERROR(FIND(",", I87, FIND(",", I87, FIND(",", I87, FIND(",", I87, FIND(",", I87, FIND(",", I87, FIND(",", I87, FIND(",", I87, FIND(",", I87) + 1) + 1) + 1) + 1) + 1) + 1) + 1) + 1) - FIND(",", I87, FIND(",", I87, FIND(",", I87, FIND(",", I87, FIND(",", I87, FIND(",", I87, FIND(",", I87, FIND(",", I87) + 1) + 1) + 1) + 1) + 1) + 1) + 1) - 1, LEN(I87)))), "")
A88: 3617380035866DG-A0J-23-29504 | B88: 3617380035866 | C88: DG-A0J-23-29504 | D88: ¿Ya escogiste tu Drink Team? Ya está disponible #LaBohemia #AfinArteMusic ? #Shorts | E88: El Fantasma, Voz De Mando | G88: AfinArte | H88: =100%-SUM(CatalogTable[[#This Row],[Artist 1 %]],CatalogTable[[#This Row],[Artist 2 %]],CatalogTable[[#This Row],[Artist 3 %]],CatalogTable[[#This Row],[Artist 4 %]],CatalogTable[[#This Row],[Artist 5 %]],CatalogTable[[#This Row],[Artist 6 %]],CatalogTable[[#This Row],[Artist 7 %]],CatalogTable[[#This Row],[Artist 8 %]],CatalogTable[[#This Row],[Artist 9%]]) -> 0.325 | I88: =IF(ISBLANK(E88),"",INDEX(UniqueArtist!B:B, MATCH(E88,UniqueArtist!A:A, 0))) -> El Fantasma, Voz de Mando | J88: =IFERROR(TRIM(LEFT(I88, IFERROR(FIND(",", I88)-1, LEN(I88)))), "") -> El Fantasma | K88: 0.175 | L88: =IFERROR(TRIM(MID(I88, FIND(",", I88) + 1, IFERROR(FIND(",", I88, FIND(",", I88) + 1) - FIND(",", I88) - 1, LEN(I88)))), "") -> Voz de Mando | M88: 0.5 | N88: =IFERROR(TRIM(MID(I88, FIND(",", I88, FIND(",", I88) + 1) + 1, IFERROR(FIND(",", I88, FIND(",", I88, FIND(",", I88) + 1) + 1) - FIND(",", I88, FIND(",", I88) + 1) - 1, LEN(I88)))), "") | P88: =IFERROR(TRIM(MID(I88, FIND(",", I88, FIND(",", I88, FIND(",", I88) + 1) + 1) + 1, IFERROR(FIND(",", I88, FIND(",", I88, FIND(",", I88, FIND(",", I88) + 1) + 1) + 1) - FIND(",", I88, FIND(",", I88, FIND(",", I88) + 1) + 1) - 1, LEN(I88)))), "") | R88: =IFERROR(TRIM(MID(I88, FIND(",", I88, FIND(",", I88, FIND(",", I88, FIND(",", I88) + 1) + 1) + 1) + 1, IFERROR(FIND(",", I88, FIND(",", I88, FIND(",", I88, FIND(",", I88, FIND(",", I88) + 1) + 1) + 1) + 1) - FIND(",", I88, FIND(",", I88, FIND(",", I88, FIND(",", I88) + 1) + 1) + 1) - 1, LEN(I88)))), "") | T88: =IFERROR(TRIM(MID(I88, FIND(",", I88, FIND(",", I88, FIND(",", I88, FIND(",", I88, FIND(",", I88, FIND(",", I88) + 1) + 1) + 1) + 1) + 1) + 1, IFERROR(FIND(",", I88, FIND(",", I88, FIND(",", I88, FIND(",", I88, FIND(",", I88, FIND(",", I88) + 1) + 1) + 1) + 1) + 1) - FIND(",", I88, FIND(",", I88, FIND(",", I88, FIND(",", I88, FIND(",", I88) + 1) + 1) + 1) + 1) - 1, LEN(I88)))), "") | V88: =IFERROR(TRIM(MID(I88, FIND(",", I88, FIND(",", I88, FIND(",", I88, FIND(",", I88, FIND(",", I88, FIND(",", I88, FIND(",", I88) + 1) + 1) + 1) + 1) + 1) + 1) + 1, IFERROR(FIND(",", I88, FIND(",", I88, FIND(",", I88, FIND(",", I88, FIND(",", I88, FIND(",", I88, FIND(",", I88) + 1) + 1) + 1) + 1) + 1) + 1) - FIND(",", I88, FIND(",", I88, FIND(",", I88, FIND(",", I88, FIND(",", I88, FIND(",", I88) + 1) + 1) + 1) + 1) + 1) - 1, LEN(I88)))), "") | X88: =IFERROR(TRIM(MID(I88, FIND(",", I88, FIND(",", I88, FIND(",", I88, FIND(",", I88, FIND(",", I88, FIND(",", I88, FIND(",", I88, FIND(",", I88) + 1) + 1) + 1) + 1) + 1) + 1) + 1) + 1, IFERROR(FIND(",", I88, FIND(",", I88, FIND(",", I88, FIND(",", I88, FIND(",", I88, FIND(",", I88, FIND(",", I88, FIND(",", I88) + 1) + 1) + 1) + 1) + 1) + 1) + 1) - FIND(",", I88, FIND(",", I88, FIND(",", I88, FIND(",", I88, FIND(",", I88, FIND(",", I88, FIND(",", I88) + 1) + 1) + 1) + 1) + 1) + 1) - 1, LEN(I88)))), "") | Z88: =IFERROR(TRIM(MID(I88, FIND(",", I88, FIND(",", I88, FIND(",", I88, FIND(",", I88, FIND(",", I88, FIND(",", I88, FIND(",", I88, FIND(",", I88, FIND(",", I88) + 1) + 1) + 1) + 1) + 1) + 1) + 1) + 1) + 1, IFERROR(FIND(",", I88, FIND(",", I88, FIND(",", I88, FIND(",", I88, FIND(",", I88, FIND(",", I88, FIND(",", I88, FIND(",", I88, FIND(",", I88) + 1) + 1) + 1) + 1) + 1) + 1) + 1) + 1) - FIND(",", I88, FIND(",", I88, FIND(",", I88, FIND(",", I88, FIND(",", I88, FIND(",", I88, FIND(",", I88, FIND(",", I88) + 1) + 1) + 1) + 1) + 1) + 1) + 1) - 1, LEN(I88)))), "")
A89: 3617053158724FR-S18-22-34525 | B89: 3617053158724 | C89: FR-S18-22-34525 | D89: ¿Ya están listos chavalones? #LaEnseñanzaDeLosViejos duetazo junto a @Pepe Aguilar #AfinArteMusic | E89: El Fantasma | G89: AfinArte | H89: =100%-SUM(CatalogTable[[#This Row],[Artist 1 %]],CatalogTable[[#This Row],[Artist 2 %]],CatalogTable[[#This Row],[Artist 3 %]],CatalogTable[[#This Row],[Artist 4 %]],CatalogTable[[#This Row],[Artist 5 %]],CatalogTable[[#This Row],[Artist 6 %]],CatalogTable[[#This Row],[Artist 7 %]],CatalogTable[[#This Row],[Artist 8 %]],CatalogTable[[#This Row],[Artist 9%]]) -> 0.65 | I89: =IF(ISBLANK(E89),"",INDEX(UniqueArtist!B:B, MATCH(E89,UniqueArtist!A:A, 0))) -> El Fantasma | J89: =IFERROR(TRIM(LEFT(I89, IFERROR(FIND(",", I89)-1, LEN(I89)))), "") -> El Fantasma | K89: 0.35 | L89: =IFERROR(TRIM(MID(I89, FIND(",", I89) + 1, IFERROR(FIND(",", I89, FIND(",", I89) + 1) - FIND(",", I89) - 1, LEN(I89)))), "") | N89: =IFERROR(TRIM(MID(I89, FIND(",", I89, FIND(",", I89) + 1) + 1, IFERROR(FIND(",", I89, FIND(",", I89, FIND(",", I89) + 1) + 1) - FIND(",", I89, FIND(",", I89) + 1) - 1, LEN(I89)))), "") | P89: =IFERROR(TRIM(MID(I89, FIND(",", I89, FIND(",", I89, FIND(",", I89) + 1) + 1) + 1, IFERROR(FIND(",", I89, FIND(",", I89, FIND(",", I89, FIND(",", I89) + 1) + 1) + 1) - FIND(",", I89, FIND(",", I89, FIND(",", I89) + 1) + 1) - 1, LEN(I89)))), "") | R89: =IFERROR(TRIM(MID(I89, FIND(",", I89, FIND(",", I89, FIND(",", I89, FIND(",", I89) + 1) + 1) + 1) + 1, IFERROR(FIND(",", I89, FIND(",", I89, FIND(",", I89, FIND(",", I89, FIND(",", I89) + 1) + 1) + 1) + 1) - FIND(",", I89, FIND(",", I89, FIND(",", I89, FIND(",", I89) + 1) + 1) + 1) - 1, LEN(I89)))), "") | T89: =IFERROR(TRIM(MID(I89, FIND(",", I89, FIND(",", I89, FIND(",", I89, FIND(",", I89, FIND(",", I89, FIND(",", I89) + 1) + 1) + 1) + 1) + 1) + 1, IFERROR(FIND(",", I89, FIND(",", I89, FIND(",", I89, FIND(",", I89, FIND(",", I89, FIND(",", I89) + 1) + 1) + 1) + 1) + 1) - FIND(",", I89, FIND(",", I89, FIND(",", I89, FIND(",", I89, FIND(",", I89) + 1) + 1) + 1) + 1) - 1, LEN(I89)))), "") | V89: =IFERROR(TRIM(MID(I89, FIND(",", I89, FIND(",", I89, FIND(",", I89, FIND(",", I89, FIND(",", I89, FIND(",", I89, FIND(",", I89) + 1) + 1) + 1) + 1) + 1) + 1) + 1, IFERROR(FIND(",", I89, FIND(",", I89, FIND(",", I89, FIND(",", I89, FIND(",", I89, FIND(",", I89, FIND(",", I89) + 1) + 1) + 1) + 1) + 1) + 1) - FIND(",", I89, FIND(",", I89, FIND(",", I89, FIND(",", I89, FIND(",", I89, FIND(",", I89) + 1) + 1) + 1) + 1) + 1) - 1, LEN(I89)))), "") | X89: =IFERROR(TRIM(MID(I89, FIND(",", I89, FIND(",", I89, FIND(",", I89, FIND(",", I89, FIND(",", I89, FIND(",", I89, FIND(",", I89, FIND(",", I89) + 1) + 1) + 1) + 1) + 1) + 1) + 1) + 1, IFERROR(FIND(",", I89, FIND(",", I89, FIND(",", I89, FIND(",", I89, FIND(",", I89, FIND(",", I89, FIND(",", I89, FIND(",", I89) + 1) + 1) + 1) + 1) + 1) + 1) + 1) - FIND(",", I89, FIND(",", I89, FIND(",", I89, FIND(",", I89, FIND(",", I89, FIND(",", I89, FIND(",", I89) + 1) + 1) + 1) + 1) + 1) + 1) - 1, LEN(I89)))), "") | Z89: =IFERROR(TRIM(MID(I89, FIND(",", I89, FIND(",", I89, FIND(",", I89, FIND(",", I89, FIND(",", I89, FIND(",", I89, FIND(",", I89, FIND(",", I89, FIND(",", I89) + 1) + 1) + 1) + 1) + 1) + 1) + 1) + 1) + 1, IFERROR(FIND(",", I89, FIND(",", I89, FIND(",", I89, FIND(",", I89, FIND(",", I89, FIND(",", I89, FIND(",", I89, FIND(",", I89, FIND(",", I89) + 1) + 1) + 1) + 1) + 1) + 1) + 1) + 1) - FIND(",", I89, FIND(",", I89, FIND(",", I89, FIND(",", I89, FIND(",", I89, FIND(",", I89, FIND(",", I89, FIND(",", I89) + 1) + 1) + 1) + 1) + 1) + 1) + 1) - 1, LEN(I89)))), "")
